Workbook

Sheet Liste de projets 
A1: LISTE DES PROJETS CIAU
A4: ITEM | B4: REFERENCE | C4: DESIGNATION | D4: MAÎTRE D'OUVRAGE | E4: CONTRAT MOE | F4: ETAT | G4: PHASE ACTUELLE | H4: Potentiel
A5: =A6+1 -> 24
A6: =A7+1 -> 23 | B6: PRI/..-…/PR | C6: Projet de construction d'un immeuble R+7 à Nyekonakpoe | D6: Victor EHE | E6: Projet de contrat | F6: En cours
A7: =A8+1 -> 22 | B7: PRI/..-.../PR | C7: Projet de construction du centre commercial K2T | D7: KLASS TOSSOU Tinos | E7: Projet de contrat | F7: En cours
A8: =A9+1 -> 21 | B8: RES/..-.../PR | C8: Projet de construction d'une villa duplex F4 à Amlamé | D8: Perso | F8: En cours
A9: =A10+1 -> 20 | B9: RES/1118/PR | C9: Projet de réabilitation de villas jumellées à Nyekonakpoe | D9: DOSSA | E9: Signé et en suivi | F9: En cours
A10: =A11+1 -> 19 | B10: IND/..-.../IN | C10: Projet de construction d'une crèche garderie | D10: BOAD | E10: Projet de contrat | F10: En cours
A11: =A12+1 -> 18 | B11: RES/..-.../PR | C11: Projet de construction d'un immeuble résidentiel à Hedzranawe | D11: Mme Bella | E11: Projet de contrat | F11: En cours
A12: =A13+1 -> 17 | B12: IND/..-.../IN | C12: Projet de construction de la gare Amou Oblo | D12: Mairie Amou Oblo | E12: Projet de contrat | F12: En cours
A13: =A14+1 -> 16 | B13: RES/..-.../IN | C13: Projet de constrcution d'une résidence secondaire à Alogavi | D13: Ministre | E13: Projet de contrat | F13: En cours
A14: =A15+1 -> 15 | B14: ='Fiche Activité CIAU'!B1524 -> Villa06/02-025/LT | C14: Projet de construction d'une éco résidence à Agbodrafo | D14: M SODATONOU | E14: Projet de contrat | F14: En cours
A15: =A16+1 -> 14 | B15: ='Fiche Activité CIAU'!B1522 -> US01/03-025/LT | C15: Projet de construction usine Sofina | D15: SOFINA | E15: Projet de contrat | F15: En cours
A16: =A17+1 -> 13 | B16: IR7/05-2024/LT | C16: Projet de construction d'une résidence de M. BAROUD | D16: M. BAROUD
A17: =A18+1 -> 12 | B17: IR8/06-024/LT | C17: Projet de construction de la résidence Les merveilles | D17: AGBOMSON | E17: Contrat à vérifier | F17: En cours
A18: =A19+1 -> 11 | B18: Villa04/06-024/LT | C18: Projet de construction de villas jumellées à Hedzranawe | D18: D'ALMEIDA | E18: Signé et en suivi | F18: En cours
A19: =A20+1 -> 10 | B19: Eg01/04-024/LT | C19: Projet de construction d'une église presbytérienne | D19: Mme ANTHONY | E19: Signé et en suivi | F19: En cours
A20: =A21+1 -> 9
A21: =A22+1 -> 8 | B21: IND/..-.../IN | C21: Projet SIMANDOU 2040 | D21: ORABANK | F21: Dormant
A22: =A23+1 -> 7 | C22: Projet de construction de vestiaires pour stade | D22: MAY | F22: Dormant
A23: =A24+1 -> 6 | B23: ='Fiche Activité CIAU'!B1521 -> IR11/11-024/LT | C23: ='Fiche Activité CIAU'!A1521 -> Projet Grunitzky | D23: Grunitzky | F23: Dormant
A24: =A25+1 -> 5 | B24: ='Fiche Activité CIAU'!B1511 -> PNHG 03/01-2025 | C24: Projet de construction d'un R+14 - Antik Building | D24: PNHG | F24: Dormant
A25: =A26+1 -> 4 | B25: IAF15/01-2023/LT | C25: Tour Mono | F25: Dormant
A26: =A27+1 -> 3 | B26: =#REF! -> #REF! | C26: Projet de construction d'un immeuble résidentiel R+5 | D26: TAY Benoit Biova | F26: Dormant
A27: =A28+1 -> 2
A28: 1 | C28: Site web - Vitrine du cabinet | D28: CIAU | F28: En cours | G28: Programmation
A30: =#REF!-1 -> #REF! | B30: Villa02/04-024/LT | C30: Résidence Luc Arthur ADJOU
A37: Voici une liste de projets CIAU datant d'avant 2020, dont je souhaiterais connaître les états afin de les introduire sur notre nouvelle liste de projets en cours ou dormant ?
A39: ITEM | B39: REFERENCE | C39: DESIGNATION | D39: MAÎTRE D'OUVRAGE | E39: HONORAIRE | F39: ETAT | G39: SOLDE | H39: Potentiel
A40: =#REF!-1 -> #REF! | B40: RES/0120/PR | C40: MME KOUMETSRON Anti Edem | E40: 4000000 | G40: 3500000
A41: =A40-1 -> #REF! | B41: REB/0120/PR | C41: COMEX (M. GBIKPI) | E41: 42000000 | G41: 32000000
A42: =A41-1 -> #REF! | B42: RES/0220/PR | C42: M. AZIAGBE (Villa R+1) | E42: 4000000
A43: =A42-1 -> #REF! | B43: RES/0320/PR | C43: MME EGUE Lauraine (Villa R+1) | E43: 750000 | G43: 450000
A44: =A43-1 -> #REF! | B44: RES/0420/PR | C44: MME APEDO | E44: Pas d'honoraire
A45: =A44-1 -> #REF! | B45: RES/0420/PR | C45: MME MAKEDA | E45: 1250000 | G45: 1000000
A46: =A45-1 -> #REF! | B46: RES/0120/PR | C46: MME NORMAN (SITO AEROPORT) | E46: 750000 | G46: 0
A47: =A46-1 -> #REF! | B47: RES/0420/PR | C47: M. MEY (Abidjan) | E47: 20000000 | G47: 0
A48: =A47-1 -> #REF! | B48: PRI/0220/IN | C48: MME NORMAN (CENTRE COMMERCIAL ADIDOGOME) | E48: 1250000 | G48: 0
A49: =A48-1 -> #REF! | B49: RES/0420/PR | C49: M. MEY (ADEWI) | E49: 1750000 | G49: 0
A50: =A49-1 -> #REF! | B50: RES/1119/PR | C50: M. ASSILEVI | E50: 250000 | G50: 0
...

Sheet Fiche de Suivi
B2: Exemples de Projets :
B3: Résidentiel (Privé) | D3: RES/…./PR
B4: Bureaux | D4: BUR/…./PR
B5: Résidentiel & Bureaux | D5: REB/…./PR
B6: Hôtel | D6: HOT/…./PR
B7: Hospitalier | D7: HOS/…./PR
B8: Programme Immobiler | D8: PRI/…./PR
B9: Indusriel (Institutionnel) | D9: IND/..-.../IN
B17: FICHE DE SUIVI PROJET
A19: 3 | D19: REFERENCE : | E19: IR6/02-2023/LT
A22: ITEM | B22: IDENTITE DU PROJET | E22: COMMENTAIRES - AJUSTEMENTS
B23: Maitre d'Ouvrage | D23: M. TAY Komi Biova Benoit
B24: Responsable des Etudes | D24: M. Thiombiano Franck
B25: Consultant extérieur
B28: DESCRIPTIF DU PROJET : IMMEUBLE RESIDENTIEL R+5 COCODY ABIDJAN
B29: Projet de construction d'un immeuble résidentiel R+5 à Cocody 2 Plateaux
B30: Les Citéales d’Angré.
B31: L’ensemble se décline en deux ailes séparées par un patio, une cage d’ascenseur et d’escaliers avec vue panoramique sur le patio. L’aile B située en façade postérieure comprend : • Huit (08) appartements de type F3 de surface moyenne habitable de 160 m², • Un Loft de type F4 d’une surface habitable de 285 m² L’aile A donnant sur la façade principale comprend : • Quatre (04) appartements de type F4 de surface moyenne habitable de 187 m², • Un Loft de type F4 d’une surface habitable à 190 m² Soit au total 14 appartements dont : 2 Lofts, 4 appartements F4, et 8 appartements de type F3. Au titre des espaces communs, Il est prévu : • Un hall d’entrée à contrôle d’accès sécurisé • Dix neuf (19) places de parkings dont : 04 places pour les deux Lofts, 07 places pour les quatre F4 et 08 pour les F3.
B33: LIVRABLES (Etats d'avancement) | E33: COMPTABILITE
B34: Contrat | E34: Honoraires :52 500 000 Fcfa | F34: Solde
B35:  Etudes préliminaires (EP) | D35: x | E35: Acompte 1 : A la signature de contrat de maîtrise d’œuvre | F35: 8500000
B36:  Avant-Projet Sommaire (APS) | D36: x | E36: Acompte 2 : A la remise de l’Avant -projet | F36: 10000000
B37:  Avant-Projet Détaillé (APD) | D37: x | E37: Acompte 3 : A la remise du Projet définitif et Instruction du Permis de Construire | F37: 5000000
B38:  Instruction du Permis de Construire (IPC) | D38: x | E38: Acompte 4 : A la remise des Plans d’exécution, devis quantitatif et estimatif des travaux | F38: 9000000
B39:  Projet de Conception Général (PCG) | E39: Acompte 5 : A la notification de démarrage des travaux | F39: 5000000
B40:  Dossier de Consultation des Entreprises (DCE) | E40: Acompte 6 : Solde par décomptes mensuels suivant avancement des travaux | F40: 15000000
B41:  Mise au Point des Marchés de Travaux (MDT | E41: TOTAL | F41: =SUM(F35:F40) -> 52500000
B48: TRAVAUX
B54: FICHE DE SUIVI PROJET
A56: 4 | D56: REFERENCE : | E56: ='Liste de projets '!B25 -> IAF15/01-2023/LT
A59: ITEM | B59: IDENTITE DU PROJET | E59: COMMENTAIRES - AJUSTEMENTS
B60: Maitre d'Ouvrage | D60: ='Fiche Activité CIAU'!#REF! -> #REF!
B61: Responsable des Etudes | D61: M. Thiombiano Franck
B62: Consultant extérieur
B65: DESCRIPTIF DU PROJET
B66: Construction
B72: LIVRABLES (Etats d'avancement) | E72: COMPTABILITE
B73: Contrat | E73: Honoraires : | F73: Solde
B74: APS | D74: Esquisses livrées, attente retour client | E74: Acompte 1 :
B75: ADD | E75: Acompte 2
...

Sheet Fiche Activité CIAU
A1: FICHE ACTIVITE CIAU
A2: Mois : FEVRIER 2026
A4: Semaine du 16/02 au 21/02/2026
A5: DESIGNATION | C5: RESPONSABLE | D5: ACTIVITES SEMAINE | F5: DELAI | G5: OBSERVATIONS
A6: Responsable Administratif et Financier | C6: M. Eric KOUMADO
A15: Responsable Technique Archi | C15: M. Cédric GBAGBA
A27: Responsable Technique œuvres secondaires | C27: M. Augustin AKOUVI
A38: Logistique & Divers | C38: Mlle Pierrette TCHINDI
A48: FICHE ACTIVITE CIAU
A49: Mois : FEVRIER 2026
A51: Semaine du 09/02 au 14/02/2026
A52: DESIGNATION | C52: RESPONSABLE | D52: ACTIVITES SEMAINE | F52: DELAI | G52: OBSERVATIONS
A53: Responsable Administratif et Financier | C53: M. Eric KOUMADO
A62: Responsable Technique Archi | C62: M. Cédric GBAGBA
A74: Responsable Technique œuvres secondaires | C74: M. Augustin AKOUVI
A85: Logistique & Divers | C85: Mlle Pierrette TCHINDI
A93: FICHE ACTIVITE CIAU
A94: Mois : FEVRIER 2026
A96: Semaine du 02/02 au 07/02/2026
A97: DESIGNATION | C97: RESPONSABLE | D97: ACTIVITES SEMAINE | F97: DELAI | G97: OBSERVATIONS
A98: Responsable Administratif et Financier | C98: M. Eric KOUMADO
A107: Responsable Technique Archi | C107: M. Cédric GBAGBA
A119: Responsable Technique œuvres secondaires | C119: M. Augustin AKOUVI
A130: Logistique & Divers | C130: Mlle Pierrette TCHINDI
A139: FICHE ACTIVITES CIAU
A141: Semaine du 25/03 au 29/03/2024
A142: TACHES | B142: REFERENCE | C142: RESPONSABLE | D142: ACTIVITES SEMAINE | F142: DELAI | G142: OBSERVATIONS
A143: Etudes Architecturales et Techniques | C143: M. Franck THIOMBIANO
A144: Tour Mono | B144: IAF15/01-2023/LT | D144: Aménagements intérieurs
A145: Barben | B145: IR6/02-2023/LT | D145: Pc- attente notice de sécurité incendie
A146: Boad - Guérites | B146: BOAD 05/2023/LT | D146: Réunion de cadrage avec la sécurité Boad
A147: Boad - Bureaux DPA | B147: BOAD 06/2024/LT | D147: Aménagements intérieurs Attente auscultation de la structure existante
A148: Kara | B148: PNHG 01/05-2023 | D148: Conception architecturale en cours
A149: Villa Mme Anthony | B149: Villa01/11-2023/LT | D149: Plan de plomberie - électricité
A152: Suivis Etudes et Travaux | C152: M. Augustin AKOUVI
A153: NSIA Totsi | B153: NSIA 01/08-2022 | D153: Envoi à M. SEGBEDJI du courrier concernant les travaux supplémentaires de ELCO - NSIA TOTSI | F153: Le 25/03/2024
A154: NSIA Dapaong | B154: NSIA 02/08-2022 | D154: Signature PV de Réception provisoire avec levées de réserves NETIS - NSIA DAPAONG | F154: Le 26/03/2024
A155: Mise à jour des fiches de suivi projets | D155: En cours
A159: Administratives et Financières | C159: M. Erick KOUMADO
A169: Logistique & Divers | C169: Mlle Abigaël AZIATI
...

Sheet Archives
A2: ITEM | B2: REFERENCE | C2: DESIGNATION | D2: MAÎTRE D'OUVRAGE | E2: CONTRAT MOE | F2: ETAT | G2: PHASE ACTUELLE | H2: Potentiel
B7: Villa05/02-025/LT | C7: Projet deconstruction d'une villa F5 | D7: Mr Homawoo | H7: *
B8: IR9/11-024/LT | C8: Projet de construction d'un immeuble R+3 | D8: Mr Akoete | H8: *
B9: PNHG 02/12-2024 | C9: Résidence Bien - Etre | D9: PNHG | H9: ?
B10: IR6/02-2023/LT | C10: Projet d'aménagement d'une terrasse piscine | D10: Mme BARBEN | H10: *
B11: BOAD 10/2024/LT | C11: BOAD - Bureaux DPA | D11: BOAD | H11: Bouclé
B12: BOAD 06/2024/LT | C12: BOAD - Salle d'audience du VP | D12: BOAD | H12: Bouclé
B13: BOAD 07/2023/LT | C13: BOAD - Villa Vice Président | D13: BOAD | H13: Bouclé
B14: BOAD 05/2023/LT | C14: BOAD - centre de loisirs | D14: BOAD | H14: Bouclé
B15: BOAD 08/2024/LT | C15: BOAD - Centre de documentation | D15: BOAD | H15: Bouclé
B16: BOAD 09/2024/LT | C16: BOAD - Parkings | D16: BOAD | H16: Bouclé
B17: Villa01/11-2023/LT | C17: Villa Mme ANTHONY | D17: Mme ANTHONY | H17: Bouclé
B18: PNHG 01/05-2023 | C18: KARA | H18: Bouclé
A19: #REF! | B19: NSIA 01/08-2022 | C19: NSIA Totsi | H19: *
A20: #REF! | B20: NSIA 02/08-2022 | C20: NSIA Dapaong | H20: Bouclé
A21: #REF! | B21: CEFOP01/05-024 | C21: Projet CEFOP - KLEME | H21: Bouclé
A22: #REF! | B22: Villa03/10-023/LT | C22: Projet de deux villas sis à Aflao de Mr ATAHI | D22: M. ATAHI | H22: *
A23: #REF! | B23: Villa 01/04-2024/LT | C23: Cédric ASSIGNON | E23: Pas d'honoraire | H23: *
A24: #REF! | C24: Projet Mme Bra | H24: *
A25: #REF! | C25: Concours jardin botanique | H25: *
A26: #REF! | B26: Villa03/10-023/LT | C26: ATAHI IRIS et KIM | H26: *
B31: BUR/0320/IN | C31: BOAD | E31: 18000000 | G31: 12000000
B32: RES/0615/PR | C32: DR JAMES | E32: 750000 | G32: 0
B33: RES/1014/PR | C33: MME LAURE | H33: Non rentable
B34: RES/0617/PR | C34: M. ATAYI Eric | E34: 1150000 | G34: 800000
B35: RES/1114/PR | C35: M. GUERALD | E35: 5000000 | G35: 2500000 | H35: Non rentable
B36: RES/0617/PR | C36: M. MEY (Villas ACCRA) | E36: 2500000 | G36: 2000000
B37: HOP/0816/PR | C37: CLINIQUE TAAMBA | H37: Non rentable
B38: RES/0516/PR | C38: MME VIAZ(Résidence TOKOIN HOPITAL) | E38: Pas de contrat
B39: PRI/0516/PR | C39: MME VIAZ(IMMEUBLE) | E39: Pas de contrat
B40: BUR/0620/PR | C40: Siège Immeuble EGC | E40: Pas de contrat
B41: RES/0119/PR | C41: Projet Résidence M. Hervé SODATONOU | E41: Pas de contrat
B42: RES/0217/PR | C42: Projet M. ATSU (Villa) | G42: 0
B43: PHA/1118/PR | C43: MME LOUKOU (Pharmacie) | E43: 26250000 | G43: 26250000 | H43: Rien payé
B44: RES/1118/PR | C44: MME LOUKOU (Appartement) | E44: 55000000 | G44: 55000000 | H44: Rien payé
B45: RES/1118/PR | C45: M. EHE (KPOGAN PLAGE) | E45: Pas commencé
B46: RES/1118/PR | C46: M. GBIPKI (Villa)
B47: RES/1118/PR | C47: M. DOSSAH (VILLAGE) | E47: RAS
B48: RES/1118/PR | C48: M. DOSSAH (NYEKONAKPOE) | E48: RAS
B49: PRI/1118/PR | C49: HOTEL NOURA (ABIDJAN) | E49: RAS
...

Sheet Liste des contrats
A4: ITEMS | B4: REFERENCES | C4: DESIGNATION | D4: ETAT | E4: DECLENCHEMENT FACTURATION | F4: OBSERVATIONS
A5: =A6+1 -> 110
A6: =A7+1 -> 109
A7: =A8+1 -> 108 | B7: ='Fiche Activité CIAU'!B296 -> #REF! | C7: ='Fiche Activité CIAU'!A296 -> M. TAY Komi Biova Benoit | D7: En cours
A8: =A9+1 -> 107 | B8: ='Fiche Activité CIAU'!B146 -> BOAD 05/2023/LT | C8: ='Fiche Activité CIAU'!A146 -> Boad - Guérites | D8: En cours
A9: =A10+1 -> 106 | B9: ='Fiche Activité CIAU'!B147 -> BOAD 06/2024/LT | C9: ='Fiche Activité CIAU'!A298 -> Boad - centre de loisirs | D9: En cours
A10: =A11+1 -> 105 | B10: ='Fiche Activité CIAU'!B299 -> BOAD 07/2023/LT | C10: ='Fiche Activité CIAU'!A299 -> Boad - Centre de documentation | D10: En cours
A11: =A12+1 -> 104 | B11: ='Fiche Activité CIAU'!B300 -> BOAD 08/2024/LT | C11: ='Fiche Activité CIAU'!A300 -> Boad - Bureaux DPA | D11: En cours
A12: =A13+1 -> 103 | B12: ='Fiche Activité CIAU'!B301 -> BOAD 09/2024/LT | C12: ='Fiche Activité CIAU'!A301 -> Boad - villa vice président | D12: En cours
A13: =A14+1 -> 102 | B13: ='Fiche Activité CIAU'!B302 -> Villa01/11-2023/LT | C13: ='Fiche Activité CIAU'!A302 -> Villa Mme Anthony | D13: En cours
A14: =A15+1 -> 101 | B14: CC01/04-2019 | C14: Centre Commercial GTA SHOP'IN Lomé | D14: En cours
A15: =A16+1 -> 100 | B15: ='Fiche Activité CIAU'!B148 -> PNHG 01/05-2023 | C15: ='Fiche Activité CIAU'!A148 -> Kara | D15: En cours
A16: =A17+1 -> 99 | B16: ='Fiche Activité CIAU'!B304 -> Villa02/04-024/LT | C16: ='Fiche Activité CIAU'!A304 -> Résidence Luc Arthur ADJOU | D16: En cours
A17: =A18+1 -> 98 | B17: ='Fiche Activité CIAU'!B153 -> NSIA 01/08-2022 | C17: ='Fiche Activité CIAU'!A153 -> NSIA Totsi | D17: En cours
A18: =A19+1 -> 97 | B18: ='Fiche Activité CIAU'!B154 -> NSIA 02/08-2022 | C18: ='Fiche Activité CIAU'!A154 -> NSIA Dapaong | D18: En cours
A19: =A20+1 -> 96 | B19: RES/0120/PR | C19: MME KOUMETSRON Anti Edem | D19: En cours
A20: =A21+1 -> 95 | B20: REB/0120/PR | C20: COMEX (M. GBIKPI) | D20: En cours
A21: =A22+1 -> 94 | B21: RES/0220/PR | C21: M. AZIAGBE (Villa R+1) | D21: En cours
A22: =A23+1 -> 93 | B22: RES/0320/PR | C22: MME EGUE Lauraine (Villa R+1) | D22: En cours
A23: =A24+1 -> 92 | B23: RES/0420/PR | C23: MME APEDO | D23: En cours
A24: =A25+1 -> 91 | B24: RES/0420/PR | C24: MME MAKEDA | D24: En cours
A25: =A26+1 -> 90 | B25: RES/0120/PR | C25: MME NORMAN (SITO AEROPORT) | D25: En cours
A26: =A27+1 -> 89 | B26: RES/0420/PR | C26: M. MEY (Abidjan) | D26: En cours
A27: =A28+1 -> 88 | B27: PRI/0220/IN | C27: MME NORMAN (CENTRE COMMERCIAL ADIDOGOME) | D27: En cours
A28: =A29+1 -> 87 | B28: RES/0420/PR | C28: M. MEY (ADEWI) | D28: En cours
A29: =A30+1 -> 86 | B29: RES/1119/PR | C29: M. ASSILEVI | D29: En cours
A30: =A31+1 -> 85 | B30: BUR/1214/IN | C30: BIDC (Réhabilitation) | D30: En cours
... A81: =A82+1 -> 34 | B81: RES/1118/PR | C81: M. AZIABLE (ACCRA) | D81: Obsolète
A82: =A83+1 -> 33 | B82: 43435 | C82: EPP AGOTEKPE | D82: Obsolète
A83: =A84+1 -> 32 | B83: 42736 | C83: CIM TOGO (Permis) | D83: Obsolète
A84: =A85+1 -> 31 | B84: 42887 | C84: BIDC (TOURNIQUET) | D84: Obsolète
A85: =A86+1 -> 30 | B85: 43405 | C85: FOUAD (Immeuble) | D85: Obsolète
A86: =A87+1 -> 29 | B86: 43405 | C86: BIDC (CONTRÔLE D'ACCES) | D86: Obsolète
A87: =A88+1 -> 28 | B87: 43405 | C87: ZOTCHI M. (Guérite) | D87: Obsolète
A88: =A89+1 -> 27 | B88: RES/1119/PR | C88: COMPAORE | D88: Obsolète
A89: =A90+1 -> 26 | B89: BUR/1119/PR | C89: COMPAORE | D89: Obsolète
A90: =A91+1 -> 25 | B90: PRI/…./PR | C90: MME FAVIN (Centre commercial) | D90: Obsolète
A91: =A92+1 -> 24 | B91: PRI/…./PR | C91: MME FAVIN (Piscine) | D91: Obsolète
A92: =A93+1 -> 23 | B92: PRI/…./PR | C92: M. AJAVON | D92: Obsolète
A93: =A94+1 -> 22 | B93: PRI/…./PR | C93: M. NANTOB | D93: Obsolète
...
